\\ Exceptions Handling â€” Function throwing an exception


In Go, while we don't have traditional exceptions as in some other programming languages, we can simulate the concept of a function "throwing an exception" using the `panic` function. When a function encounters an unrecoverable error, it can call `panic` to halt the normal flow of execution and signal that something went wrong.

### Example: Function Throwing an Exception

Here's an example of a function that "throws an exception" using `panic`, and how you can call this function while handling the potential panic:

```go
package main

import (
	"fmt"
)

func main() {
	fmt.Println("Starting the program")

	// Call the function that may throw an exception
	handleFunction()

	fmt.Println("Program continues execution")
}

func handleFunction() {
	defer func() {
		if err := recover(); err != nil {
			fmt.Println("Recovered from panic:", err)
		}
	}()

	throwException("Something went wrong!")

	fmt.Println("This line will not be executed")
}

func throwException(message string) {
	panic(message)
}
```

### Explanation

1. **Starting the Program:**
   The program begins and prints "Starting the program".

2. **Handling Potential Panic with `recover`:**
   ```go
   defer func() {
       if err := recover(); err != nil {
           fmt.Println("Recovered from panic:", err)
       }
   }()
   ```
   In the `handleFunction` function, a deferred function is set up to catch and handle any panic that occurs. This function calls `recover` to intercept the panic, allowing the program to handle the error gracefully.

3. **Throwing an Exception:**
   ```go
   throwException("Something went wrong!")
   ```
   The `throwException` function is called, which in turn calls `panic` with the provided message. This simulates "throwing an exception".

4. **Recovering from Panic:**
   The deferred function catches the panic using `recover`, prints the panic message, and prevents the program from crashing. Execution continues after the deferred function.

### Practical Use Case: Database Operation

Consider a scenario where a function interacts with a database and might encounter an error. We can use `panic` and `recover` to handle such cases:

```go
package main

import (
	"database/sql"
	"fmt"
	"log"

	_ "github.com/go-sql-driver/mysql"
)

func main() {
	err := performDatabaseOperation()
	if err != nil {
		log.Fatalf("Failed to perform database operation: %v", err)
	}

	fmt.Println("Program continues execution")
}

func performDatabaseOperation() (err error) {
	defer func() {
		if r := recover(); r != nil {
			err = fmt.Errorf("recovered from panic: %v", r)
		}
	}()

	// Simulate a database operation that may panic
	db, err := sql.Open("mysql", "user:password@/dbname")
	if err != nil {
		panic("failed to connect to the database")
	}
	defer db.Close()

	// Perform some database operation
	// ...

	// Simulate a panic
	panic("unexpected database error")

	return nil
}
```

### Explanation

1. **Perform Database Operation:**
   The `performDatabaseOperation` function performs a database operation and is set up to handle panics.

2. **Deferred Function for Recovery:**
   ```go
   defer func() {
       if r := recover(); r != nil {
           err = fmt.Errorf("recovered from panic: %v", r)
       }
   }()
   ```
   This deferred function catches any panic that occurs within `performDatabaseOperation` and sets the named return variable `err` to an appropriate error message.

3. **Simulated Database Panic:**
   ```go
   panic("unexpected database error")
   ```
   The function simulates a panic during a database operation. This triggers the deferred recovery function, which catches the panic and returns an error.

4. **Handling the Error in `main`:**
   In the `main` function, we check if `performDatabaseOperation` returns an error and log a fatal message if it does. This ensures that we handle the error gracefully and provide meaningful feedback to the user.

### Conclusion

In Go, you can simulate throwing and catching exceptions using `panic` and `recover`. This approach allows you to handle unexpected errors gracefully, ensuring that your program can recover from panics and continue execution. Proper use of `panic` and `recover`, combined with deferred functions, helps maintain robust and reliable applications.